Workbook

Sheet RAW_Data
A2: Please fill in to below blank.
A3: DUT name | C3: FW ver | E3: used Python script | G3: DS-TWR_xxxxxxxxxxxxx.py
A4: Channel | C4: Anntena pitch | E4: XXmm
A6: Please share us raw data of more than 10 times measurement data, not only Average data.
A7: Example data for 30times measurement.
A8: H | B8: V | E8: NLOS | F8: Dist | G8: AoA1 | H8: AoA2 | I8: PDoA1 | J8: PDoA2
A9: -60 | B9: -60 | C9: ***(0) | D9: NLos | E9: 0 | F9: 191 | G9: -60 | H9: -60 | I9: 133.57812 | J9: -63.28125
A10: -60 | B10: -60 | C10: ***(1) | D10: NLos | E10: 0 | F10: 188 | G10: -60 | H10: -60 | I10: 134.78125 | J10: -54.84375
A11: -60 | B11: -60 | C11: ***(2) | D11: NLos | E11: 0 | F11: 190 | G11: -60 | H11: -60 | I11: 133.48438 | J11: -63.046875
A12: -60 | B12: -60 | C12: ***(3) | D12: NLos | E12: 0 | F12: 187 | G12: -60 | H12: -60 | I12: 127.625 | J12: -61.90625
A13: -60 | B13: -60 | C13: ***(4) | D13: NLos | E13: 0 | F13: 183 | G13: -60 | H13: -60 | I13: 132.85938 | J13: -65.109375
A14: -60 | B14: -60 | C14: ***(5) | D14: NLos | E14: 0 | F14: 189 | G14: -60 | H14: -60 | I14: 132.1875 | J14: -54.328125
A15: -60 | B15: -60 | C15: ***(6) | D15: NLos | E15: 0 | F15: 193 | G15: -60 | H15: -60 | I15: 131.73438 | J15: -62.09375
A16: -60 | B16: -60 | C16: ***(7) | D16: NLos | E16: 0 | F16: 184 | G16: -60 | H16: -60 | I16: 126.03125 | J16: -57.1875
A17: -60 | B17: -60 | C17: ***(8) | D17: NLos | E17: 0 | F17: 186 | G17: -60 | H17: -60 | I17: 126.89062 | J17: -61.515625
A18: -60 | B18: -60 | C18: ***(9) | D18: NLos | E18: 0 | F18: 182 | G18: -60 | H18: -60 | I18: 131.9375 | J18: -60.09375
A19: -60 | B19: -60 | C19: ***(10) | D19: NLos | E19: 0 | F19: 186 | G19: -60 | H19: -60 | I19: 132.39062 | J19: -67.78125
A20: -60 | B20: -60 | C20: ***(11) | D20: NLos | E20: 0 | F20: 182 | G20: -60 | H20: -60 | I20: 132.8125 | J20: -68.765625
... A3671: 60 | B3671: 60 | C3671: ***(29) | D3671: NLos | E3671: 0 | F3671: 186 | G3671: -60 | H3671: -60 | I3671: -139.23438 | J3671: 37.375

Sheet Average_STDEV
A2: Example: Average and STDEV with 30times measurement
A3: Average | I3: STDEV
A4: H | B4: V | C4: NLOS | D4: Dist | E4: AoA1 | F4: AoA2 | G4: PDoA1 | H4: PDoA2 | I4: Dist | J4: AoA1 | K4: AoA2 | L4: PDoA1 | M4: PDoA2
A5: =AVERAGE(RAW_Data!A9:A38) -> -60 | B5: =AVERAGE(RAW_Data!B9:B38) -> -60 | C5: =AVERAGE(RAW_Data!E9:E38) -> 0 | D5: =AVERAGE(RAW_Data!F9:F38) -> 188.26667 | E5: =AVERAGE(RAW_Data!G9:G38) -> -60 | F5: =AVERAGE(RAW_Data!H9:H38) -> -60 | G5: =AVERAGE(RAW_Data!I9:I38) -> 130.90365 | H5: =AVERAGE(RAW_Data!J9:J38) -> -60.911979 | I5: =STDEV(RAW_Data!F9:F38) -> 4.2012587 | J5: =STDEV(RAW_Data!G9:G38) -> 0 | K5: =STDEV(RAW_Data!H9:H38) -> 0 | L5: =STDEV(RAW_Data!I9:I38) -> 2.9723863 | M5: =STDEV(RAW_Data!J9:J38) -> 4.1327918
A6: =AVERAGE(RAW_Data!A39:A68) -> -48 | B6: =AVERAGE(RAW_Data!B39:B68) -> -60 | C6: =AVERAGE(RAW_Data!E39:E68) -> 0 | D6: =AVERAGE(RAW_Data!F39:F68) -> 181.63333 | E6: =AVERAGE(RAW_Data!G39:G68) -> -60 | F6: =AVERAGE(RAW_Data!H39:H68) -> -60 | G6: =AVERAGE(RAW_Data!I39:I68) -> 101.52552 | H6: =AVERAGE(RAW_Data!J39:J68) -> -87.848438 | I6: =STDEV(RAW_Data!F39:F68) -> 7.7436663 | J6: =STDEV(RAW_Data!G39:G68) -> 0 | K6: =STDEV(RAW_Data!H39:H68) -> 0 | L6: =STDEV(RAW_Data!I39:I68) -> 2.3059067 | M6: =STDEV(RAW_Data!J39:J68) -> 2.9210124
A7: =AVERAGE(RAW_Data!A69:A98) -> -36 | B7: =AVERAGE(RAW_Data!B69:B98) -> -60 | C7: =AVERAGE(RAW_Data!E69:E98) -> 0 | D7: =AVERAGE(RAW_Data!F69:F98) -> 182.86667 | E7: =AVERAGE(RAW_Data!G69:G98) -> -60 | F7: =AVERAGE(RAW_Data!H69:H98) -> -60 | G7: =AVERAGE(RAW_Data!I69:I98) -> 69.159375 | H7: =AVERAGE(RAW_Data!J69:J98) -> -105.31719 | I7: =STDEV(RAW_Data!F69:F98) -> 6.8366827 | J7: =STDEV(RAW_Data!G69:G98) -> 0 | K7: =STDEV(RAW_Data!H69:H98) -> 0 | L7: =STDEV(RAW_Data!I69:I98) -> 1.3034659 | M7: =STDEV(RAW_Data!J69:J98) -> 2.8197618
A8: =AVERAGE(RAW_Data!A99:A128) -> -24 | B8: =AVERAGE(RAW_Data!B99:B128) -> -60 | C8: =AVERAGE(RAW_Data!E99:E128) -> 0 | D8: =AVERAGE(RAW_Data!F99:F128) -> 188.56667 | E8: =AVERAGE(RAW_Data!G99:G128) -> -60 | F8: =AVERAGE(RAW_Data!H99:H128) -> -60 | G8: =AVERAGE(RAW_Data!I99:I128) -> 49.997396 | H8: =AVERAGE(RAW_Data!J99:J128) -> -107.7151 | I8: =STDEV(RAW_Data!F99:F128) -> 3.1697202 | J8: =STDEV(RAW_Data!G99:G128) -> 0 | K8: =STDEV(RAW_Data!H99:H128) -> 0 | L8: =STDEV(RAW_Data!I99:I128) -> 1.5019747 | M8: =STDEV(RAW_Data!J99:J128) -> 2.5453646
A9: =AVERAGE(RAW_Data!A130:A159) -> -12 | B9: =AVERAGE(RAW_Data!B130:B159) -> -60 | C9: =AVERAGE(RAW_Data!E130:E159) -> 0 | D9: =AVERAGE(RAW_Data!F130:F159) -> 187.16667 | E9: =AVERAGE(RAW_Data!G130:G159) -> -60 | F9: =AVERAGE(RAW_Data!H130:H159) -> -60 | G9: =AVERAGE(RAW_Data!I130:I159) -> 15.895833 | H9: =AVERAGE(RAW_Data!J130:J159) -> -104.69948 | I9: =STDEV(RAW_Data!F130:F159) -> 2.6663074 | J9: =STDEV(RAW_Data!G130:G159) -> 0 | K9: =STDEV(RAW_Data!H130:H159) -> 0 | L9: =STDEV(RAW_Data!I130:I159) -> 1.2830906 | M9: =STDEV(RAW_Data!J130:J159) -> 2.2319215
A10: =AVERAGE(RAW_Data!A161:A190) -> 0 | B10: =AVERAGE(RAW_Data!B161:B190) -> -60 | C10: =AVERAGE(RAW_Data!E161:E190) -> 0 | D10: =AVERAGE(RAW_Data!F161:F190) -> 187.33333 | E10: =AVERAGE(RAW_Data!G161:G190) -> -60 | F10: =AVERAGE(RAW_Data!H161:H190) -> -60 | G10: =AVERAGE(RAW_Data!I161:I190) -> -16.284896 | H10: =AVERAGE(RAW_Data!J161:J190) -> -106.35052 | I10: =STDEV(RAW_Data!F161:F190) -> 2.6305019 | J10: =STDEV(RAW_Data!G161:G190) -> 0 | K10: =STDEV(RAW_Data!H161:H190) -> 0 | L10: =STDEV(RAW_Data!I161:I190) -> 1.6251382 | M10: =STDEV(RAW_Data!J161:J190) -> 2.2393136
A11: =AVERAGE(RAW_Data!A191:A220) -> 12 | B11: =AVERAGE(RAW_Data!B191:B220) -> -60 | C11: =AVERAGE(RAW_Data!E191:E220) -> 0 | D11: =AVERAGE(RAW_Data!F191:F220) -> 187.53333 | E11: =AVERAGE(RAW_Data!G191:G220) -> -60 | F11: =AVERAGE(RAW_Data!H191:H220) -> -60 | G11: =AVERAGE(RAW_Data!I191:I220) -> -47.579167 | H11: =AVERAGE(RAW_Data!J191:J220) -> -110.71875 | I11: =STDEV(RAW_Data!F191:F220) -> 2.9680289 | J11: =STDEV(RAW_Data!G191:G220) -> 0 | K11: =STDEV(RAW_Data!H191:H220) -> 0 | L11: =STDEV(RAW_Data!I191:I220) -> 2.0410941 | M11: =STDEV(RAW_Data!J191:J220) -> 1.8686494
A12: =AVERAGE(RAW_Data!A221:A250) -> 24 | B12: =AVERAGE(RAW_Data!B221:B250) -> -60 | C12: =AVERAGE(RAW_Data!E221:E250) -> 0 | D12: =AVERAGE(RAW_Data!F221:F250) -> 186.53333 | E12: =AVERAGE(RAW_Data!G221:G250) -> -60 | F12: =AVERAGE(RAW_Data!H221:H250) -> -60 | G12: =AVERAGE(RAW_Data!I221:I250) -> -79.28125 | H12: =AVERAGE(RAW_Data!J221:J250) -> -111.45 | I12: =STDEV(RAW_Data!F221:F250) -> 2.7509664 | J12: =STDEV(RAW_Data!G221:G250) -> 0 | K12: =STDEV(RAW_Data!H221:H250) -> 0 | L12: =STDEV(RAW_Data!I221:I250) -> 2.0933841 | M12: =STDEV(RAW_Data!J221:J250) -> 3.0572599
A13: =AVERAGE(RAW_Data!A252:A281) -> 36 | B13: =AVERAGE(RAW_Data!B252:B281) -> -60 | C13: =AVERAGE(RAW_Data!E252:E281) -> 0 | D13: =AVERAGE(RAW_Data!F252:F281) -> 187.16667 | E13: =AVERAGE(RAW_Data!G252:G281) -> -60 | F13: =AVERAGE(RAW_Data!H252:H281) -> -60 | G13: =AVERAGE(RAW_Data!I252:I281) -> -92.95625 | H13: =AVERAGE(RAW_Data!J252:J281) -> -108.87969 | I13: =STDEV(RAW_Data!F252:F281) -> 2.9720924 | J13: =STDEV(RAW_Data!G252:G281) -> 0 | K13: =STDEV(RAW_Data!H252:H281) -> 0 | L13: =STDEV(RAW_Data!I252:I281) -> 0.97607768 | M13: =STDEV(RAW_Data!J252:J281) -> 1.7112894
A14: =AVERAGE(RAW_Data!A282:A311) -> 48 | B14: =AVERAGE(RAW_Data!B282:B311) -> -60 | C14: =AVERAGE(RAW_Data!E282:E311) -> 0 | D14: =AVERAGE(RAW_Data!F282:F311) -> 185.86667 | E14: =AVERAGE(RAW_Data!G282:G311) -> -60 | F14: =AVERAGE(RAW_Data!H282:H311) -> -60 | G14: =AVERAGE(RAW_Data!I282:I311) -> -114.5625 | H14: =AVERAGE(RAW_Data!J282:J311) -> -96.759375 | I14: =STDEV(RAW_Data!F282:F311) -> 3.6268475 | J14: =STDEV(RAW_Data!G282:G311) -> 0 | K14: =STDEV(RAW_Data!H282:H311) -> 0 | L14: =STDEV(RAW_Data!I282:I311) -> 2.0675185 | M14: =STDEV(RAW_Data!J282:J311) -> 3.5548106
A15: =AVERAGE(RAW_Data!A312:A341) -> 60 | B15: =AVERAGE(RAW_Data!B312:B341) -> -60 | C15: =AVERAGE(RAW_Data!E312:E341) -> 0 | D15: =AVERAGE(RAW_Data!F312:F341) -> 185.86667 | E15: =AVERAGE(RAW_Data!G312:G341) -> -60 | F15: =AVERAGE(RAW_Data!H312:H341) -> -60 | G15: =AVERAGE(RAW_Data!I312:I341) -> -145.43594 | H15: =AVERAGE(RAW_Data!J312:J341) -> -89.525521 | I15: =STDEV(RAW_Data!F312:F341) -> 2.8735816 | J15: =STDEV(RAW_Data!G312:G341) -> 0 | K15: =STDEV(RAW_Data!H312:H341) -> 0 | L15: =STDEV(RAW_Data!I312:I341) -> 1.6911098 | M15: =STDEV(RAW_Data!J312:J341) -> 2.9184991
A16: =AVERAGE(RAW_Data!A343:A372) -> -60 | B16: =AVERAGE(RAW_Data!B343:B372) -> -48 | C16: =AVERAGE(RAW_Data!E343:E372) -> 0 | D16: =AVERAGE(RAW_Data!F343:F372) -> 186.6 | E16: =AVERAGE(RAW_Data!G343:G372) -> -60 | F16: =AVERAGE(RAW_Data!H343:H372) -> -60 | G16: =AVERAGE(RAW_Data!I343:I372) -> 121.11146 | H16: =AVERAGE(RAW_Data!J343:J372) -> -65.723438 | I16: =STDEV(RAW_Data!F343:F372) -> 3.3072543 | J16: =STDEV(RAW_Data!G343:G372) -> 0 | K16: =STDEV(RAW_Data!H343:H372) -> 0 | L16: =STDEV(RAW_Data!I343:I372) -> 1.6197888 | M16: =STDEV(RAW_Data!J343:J372) -> 2.7347156 | P16: -60 | Q16: -48 | R16: -36 | S16: -24 | T16: -12 | U16: 0 | V16: 12 | W16: 24 | X16: 36 | Y16: 48 | Z16: 60
A17: =AVERAGE(RAW_Data!A373:A402) -> -48 | B17: =AVERAGE(RAW_Data!B373:B402) -> -48 | C17: =AVERAGE(RAW_Data!E373:E402) -> 0 | D17: =AVERAGE(RAW_Data!F373:F402) -> 181.93333 | E17: =AVERAGE(RAW_Data!G373:G402) -> -60 | F17: =AVERAGE(RAW_Data!H373:H402) -> -60 | G17: =AVERAGE(RAW_Data!I373:I402) -> 105.35469 | H17: =AVERAGE(RAW_Data!J373:J402) -> -65.308854 | I17: =STDEV(RAW_Data!F373:F402) -> 4.0252079 | J17: =STDEV(RAW_Data!G373:G402) -> 0 | K17: =STDEV(RAW_Data!H373:H402) -> 0 | L17: =STDEV(RAW_Data!I373:I402) -> 2.9830846 | M17: =STDEV(RAW_Data!J373:J402) -> 2.9415802 | P17: =$H$5 -> -60.911979 | Q17: =$H$6 -> -87.848438 | R17: =$H$7 -> -105.31719 | S17: =$H$8 -> -107.7151 | T17: =$H$9 -> -104.69948 | U17: =$H$10 -> -106.35052 | V17: =$H$11 -> -110.71875 | W17: =$H$12 -> -111.45 | X17: =$H$13 -> -108.87969 | Y17: =$H$14 -> -96.759375 | Z17: =$H$15 -> -89.525521
A18: =AVERAGE(RAW_Data!A404:A433) -> -36 | B18: =AVERAGE(RAW_Data!B404:B433) -> -48 | C18: =AVERAGE(RAW_Data!E404:E433) -> 0 | D18: =AVERAGE(RAW_Data!F404:F433) -> 183.96667 | E18: =AVERAGE(RAW_Data!G404:G433) -> -60 | F18: =AVERAGE(RAW_Data!H404:H433) -> -60 | G18: =AVERAGE(RAW_Data!I404:I433) -> 67.864583 | H18: =AVERAGE(RAW_Data!J404:J433) -> -82.328125 | I18: =STDEV(RAW_Data!F404:F433) -> 3.2955909 | J18: =STDEV(RAW_Data!G404:G433) -> 0 | K18: =STDEV(RAW_Data!H404:H433) -> 0 | L18: =STDEV(RAW_Data!I404:I433) -> 1.105649 | M18: =STDEV(RAW_Data!J404:J433) -> 2.9796985 | P18: =$H$16 -> -65.723438 | Q18: =$H$17 -> -65.308854 | R18: =$H$18 -> -82.328125 | S18: =$H$19 -> -98.456771 | T18: =$H$20 -> -101.54271 | U18: =$H$21 -> -97.695312 | V18: =$H$22 -> -98.851562 | W18: =$H$23 -> -100.37656 | X18: =$H$24 -> -97.242708 | Y18: =$H$25 -> -91.123958 | Z18: =$H$26 -> -80.120312
A19: =AVERAGE(RAW_Data!A434:A463) -> -24 | B19: =AVERAGE(RAW_Data!B434:B463) -> -48 | C19: =AVERAGE(RAW_Data!E434:E463) -> 0 | D19: =AVERAGE(RAW_Data!F434:F463) -> 186.13333 | E19: =AVERAGE(RAW_Data!G434:G463) -> -60 | F19: =AVERAGE(RAW_Data!H434:H463) -> -60 | G19: =AVERAGE(RAW_Data!I434:I463) -> 49.598958 | H19: =AVERAGE(RAW_Data!J434:J463) -> -98.456771 | I19: =STDEV(RAW_Data!F434:F463) -> 3.0931887 | J19: =STDEV(RAW_Data!G434:G463) -> 0 | K19: =STDEV(RAW_Data!H434:H463) -> 0 | L19: =STDEV(RAW_Data!I434:I463) -> 0.92849785 | M19: =STDEV(RAW_Data!J434:J463) -> 2.4717241 | P19: =$H$27 -> -59.176563 | Q19: =$H$28 -> -57.6625 | R19: =$H$29 -> -49.266667 | S19: =$H$30 -> -67.993229 | T19: =$H$31 -> -79.130208 | U19: =$H$32 -> -84.501563 | V19: =$H$33 -> -84.554167 | W19: =$H$34 -> -82.188021 | X19: =$H$35 -> -75.655208 | Y19: =$H$36 -> -80.870312 | Z19: =$H$37 -> -70.369792
A20: =AVERAGE(RAW_Data!A464:A493) -> -12 | B20: =AVERAGE(RAW_Data!B464:B493) -> -48 | C20: =AVERAGE(RAW_Data!E464:E493) -> 0 | D20: =AVERAGE(RAW_Data!F464:F493) -> 187.76667 | E20: =AVERAGE(RAW_Data!G464:G493) -> -60 | F20: =AVERAGE(RAW_Data!H464:H493) -> -60 | G20: =AVERAGE(RAW_Data!I464:I493) -> 13.870313 | H20: =AVERAGE(RAW_Data!J464:J493) -> -101.54271 | I20: =STDEV(RAW_Data!F464:F493) -> 3.6263721 | J20: =STDEV(RAW_Data!G464:G493) -> 0 | K20: =STDEV(RAW_Data!H464:H493) -> 0 | L20: =STDEV(RAW_Data!I464:I493) -> 0.83260267 | M20: =STDEV(RAW_Data!J464:J493) -> 2.0527006 | P20: =$H$38 -> -38.868229 | Q20: =$H$39 -> -48.125521 | R20: =$H$40 -> -41.103646 | S20: =$H$41 -> -37.356771 | T20: =$H$42 -> -43.448437 | U20: =$H$43 -> -52.529688 | V20: =$H$44 -> -58.238542 | W20: =$H$45 -> -60.752604 | X20: =$H$46 -> -64.880729 | Y20: =$H$47 -> -71.547917 | Z20: =$H$48 -> -54.879688
A21: =AVERAGE(RAW_Data!A494:A523) -> 0 | B21: =AVERAGE(RAW_Data!B494:B523) -> -48 | C21: =AVERAGE(RAW_Data!E494:E523) -> 0 | D21: =AVERAGE(RAW_Data!F494:F523) -> 187.53333 | E21: =AVERAGE(RAW_Data!G494:G523) -> -60 | F21: =AVERAGE(RAW_Data!H494:H523) -> -60 | G21: =AVERAGE(RAW_Data!I494:I523) -> -13.144792 | H21: =AVERAGE(RAW_Data!J494:J523) -> -97.695312 | I21: =STDEV(RAW_Data!F494:F523) -> 2.8251742 | J21: =STDEV(RAW_Data!G494:G523) -> 0 | K21: =STDEV(RAW_Data!H494:H523) -> 0 | L21: =STDEV(RAW_Data!I494:I523) -> 0.81073596 | M21: =STDEV(RAW_Data!J494:J523) -> 2.2920657 | P21: =$H$49 -> -13.207812 | Q21: =$H$50 -> -22.604688 | R21: =$H$51 -> -29.179688 | S21: =$H$52 -> -28.485937 | T21: =$H$53 -> -27.927083 | U21: =$H$54 -> -31.120833 | V21: =$H$55 -> -36.682812 | W21: =$H$56 -> -41.650521 | X21: =$H$57 -> -44.911979 | Y21: =$H$58 -> -48.091667 | Z21: =$H$59 -> -34.277083
A22: =AVERAGE(RAW_Data!A524:A553) -> 12 | B22: =AVERAGE(RAW_Data!B524:B553) -> -48 | C22: =AVERAGE(RAW_Data!E524:E553) -> 0 | D22: =AVERAGE(RAW_Data!F524:F553) -> 188.36667 | E22: =AVERAGE(RAW_Data!G524:G553) -> -60 | F22: =AVERAGE(RAW_Data!H524:H553) -> -60 | G22: =AVERAGE(RAW_Data!I524:I553) -> -41.611458 | H22: =AVERAGE(RAW_Data!J524:J553) -> -98.851562 | I22: =STDEV(RAW_Data!F524:F553) -> 3.0112815 | J22: =STDEV(RAW_Data!G524:G553) -> 0 | K22: =STDEV(RAW_Data!H524:H553) -> 0 | L22: =STDEV(RAW_Data!I524:I553) -> 0.8434779 | M22: =STDEV(RAW_Data!J524:J553) -> 1.9771976 | P22: =$H$60 -> 12.267708 | Q22: =$H$61 -> 17.05625 | R22: =$H$62 -> 13.063542 | S22: =$H$63 -> 4.7526042 | T22: =$H$64 -> -3.6786458 | U22: =$H$65 -> -7.0630208 | V22: =$H$66 -> -8.8130208 | W22: =$H$67 -> -9.1401042 | X22: =$H$68 -> -11.127604 | Y22: =$H$69 -> -14.572917 | Z22: =$H$70 -> -14.100521
A23: =AVERAGE(RAW_Data!A555:A584) -> 24 | B23: =AVERAGE(RAW_Data!B555:B584) -> -48 | C23: =AVERAGE(RAW_Data!E555:E584) -> 0 | D23: =AVERAGE(RAW_Data!F555:F584) -> 186.53333 | E23: =AVERAGE(RAW_Data!G555:G584) -> -60 | F23: =AVERAGE(RAW_Data!H555:H584) -> -60 | G23: =AVERAGE(RAW_Data!I555:I584) -> -74.063542 | H23: =AVERAGE(RAW_Data!J555:J584) -> -100.37656 | I23: =STDEV(RAW_Data!F555:F584) -> 3.0255616 | J23: =STDEV(RAW_Data!G555:G584) -> 0 | K23: =STDEV(RAW_Data!H555:H584) -> 0 | L23: =STDEV(RAW_Data!I555:I584) -> 1.3007216 | M23: =STDEV(RAW_Data!J555:J584) -> 2.0475858 | P23: =$H$71 -> 29.129687 | Q23: =$H$72 -> 40.236458 | R23: =$H$73 -> 42.043229 | S23: =$H$74 -> 43.428646 | T23: =$H$75 -> 36.807292 | U23: =$H$76 -> 30.056771 | V23: =$H$77 -> 24.271875 | W23: =$H$78 -> 19.579687 | X23: =$H$79 -> 12.585417 | Y23: =$H$80 -> 6.096875 | Z23: =$H$81 -> 1.9791667
A24: =AVERAGE(RAW_Data!A585:A614) -> 36 | B24: =AVERAGE(RAW_Data!B585:B614) -> -48 | C24: =AVERAGE(RAW_Data!E585:E614) -> 0 | D24: =AVERAGE(RAW_Data!F585:F614) -> 186.43333 | E24: =AVERAGE(RAW_Data!G585:G614) -> -60 | F24: =AVERAGE(RAW_Data!H585:H614) -> -60 | G24: =AVERAGE(RAW_Data!I585:I614) -> -97.141667 | H24: =AVERAGE(RAW_Data!J585:J614) -> -97.242708 | I24: =STDEV(RAW_Data!F585:F614) -> 3.2555876 | J24: =STDEV(RAW_Data!G585:G614) -> 0 | K24: =STDEV(RAW_Data!H585:H614) -> 0 | L24: =STDEV(RAW_Data!I585:I614) -> 1.314006 | M24: =STDEV(RAW_Data!J585:J614) -> 2.2542417 | P24: =$H$82 -> 35.258854 | Q24: =$H$83 -> 47.017187 | R24: =$H$84 -> 53.469792 | S24: =$H$85 -> 58.547917 | T24: =$H$86 -> 61.654167 | U24: =$H$87 -> 64.476042 | V24: =$H$88 -> 61.878646 | W24: =$H$89 -> 52.075 | X24: =$H$90 -> 33.460938 | Y24: =$H$91 -> 16.272396 | Z24: =$H$92 -> 5.875
A25: =AVERAGE(RAW_Data!A615:A644) -> 48 | B25: =AVERAGE(RAW_Data!B615:B644) -> -48 | C25: =AVERAGE(RAW_Data!E615:E644) -> 0 | D25: =AVERAGE(RAW_Data!F615:F644) -> 186.93333 | E25: =AVERAGE(RAW_Data!G615:G644) -> -60 | F25: =AVERAGE(RAW_Data!H615:H644) -> -60 | G25: =AVERAGE(RAW_Data!I615:I644) -> -116.48646 | H25: =AVERAGE(RAW_Data!J615:J644) -> -91.123958 | I25: =STDEV(RAW_Data!F615:F644) -> 3.1615506 | J25: =STDEV(RAW_Data!G615:G644) -> 0 | K25: =STDEV(RAW_Data!H615:H644) -> 0 | L25: =STDEV(RAW_Data!I615:I644) -> 1.4749715 | M25: =STDEV(RAW_Data!J615:J644) -> 1.9000391 | P25: =$H$93 -> 50.445833 | Q25: =$H$94 -> 75.047396 | R25: =$H$95 -> 81.796875 | S25: =$H$96 -> 91.769792 | T25: =$H$97 -> 91.79375 | U25: =$H$98 -> 89.828646 | V25: =$H$99 -> 88.924479 | W25: =$H$100 -> 84.254688 | X25: =$H$101 -> 63.7875 | Y25: =$H$102 -> 39.408854 | Z25: =$H$103 -> 15.173958
A26: =AVERAGE(RAW_Data!A645:A674) -> 60 | B26: =AVERAGE(RAW_Data!B645:B674) -> -48 | C26: =AVERAGE(RAW_Data!E645:E674) -> 0 | D26: =AVERAGE(RAW_Data!F645:F674) -> 187.76667 | E26: =AVERAGE(RAW_Data!G645:G674) -> -60 | F26: =AVERAGE(RAW_Data!H645:H674) -> -60 | G26: =AVERAGE(RAW_Data!I645:I674) -> -143.72031 | H26: =AVERAGE(RAW_Data!J645:J674) -> -80.120312 | I26: =STDEV(RAW_Data!F645:F674) -> 3.4808177 | J26: =STDEV(RAW_Data!G645:G674) -> 0 | K26: =STDEV(RAW_Data!H645:H674) -> 0 | L26: =STDEV(RAW_Data!I645:I674) -> 1.6701664 | M26: =STDEV(RAW_Data!J645:J674) -> 1.5851173 | P26: =$H$104 -> 69.158854 | Q26: =$H$105 -> 94.895313 | R26: =$H$106 -> 105.46771 | S26: =$H$107 -> 118.56719 | T26: =$H$108 -> 122.08333 | U26: =$H$109 -> 117.80156 | V26: =$H$110 -> 108.12969 | W26: =$H$111 -> 96.098958 | X26: =$H$112 -> 84.445312 | Y26: =$H$113 -> 62.924479 | Z26: =$H$114 -> 28.605729
A27: =AVERAGE(RAW_Data!A675:A704) -> -60 | B27: =AVERAGE(RAW_Data!B675:B704) -> -36 | C27: =AVERAGE(RAW_Data!E675:E704) -> 0 | D27: =AVERAGE(RAW_Data!F675:F704) -> 183.8 | E27: =AVERAGE(RAW_Data!G675:G704) -> -60 | F27: =AVERAGE(RAW_Data!H675:H704) -> -60 | G27: =AVERAGE(RAW_Data!I675:I704) -> 117.13229 | H27: =AVERAGE(RAW_Data!J675:J704) -> -59.176563 | I27: =STDEV(RAW_Data!F675:F704) -> 3.1117131 | J27: =STDEV(RAW_Data!G675:G704) -> 0 | K27: =STDEV(RAW_Data!H675:H704) -> 0 | L27: =STDEV(RAW_Data!I675:I704) -> 1.3109387 | M27: =STDEV(RAW_Data!J675:J704) -> 3.4362707 | P27: =$H$115 -> 86.659896 | Q27: =$H$116 -> 105.77604 | R27: =$H$117 -> 120.21823 | S27: =$H$118 -> 137.1099 | T27: =$H$119 -> 142.30573 | U27: =$H$120 -> 140.12083 | V27: =$H$121 -> 130.99323 | W27: =$H$122 -> 116.76458 | X27: =$H$123 -> 97.651562 | Y27: =$H$124 -> 73.604167 | Z27: =$H$125 -> 41.479687
A28: =AVERAGE(RAW_Data!A705:A734) -> -48 | B28: =AVERAGE(RAW_Data!B705:B734) -> -36 | C28: =AVERAGE(RAW_Data!E705:E734) -> 0 | D28: =AVERAGE(RAW_Data!F705:F734) -> 186.56667 | E28: =AVERAGE(RAW_Data!G705:G734) -> -60 | F28: =AVERAGE(RAW_Data!H705:H734) -> -60 | G28: =AVERAGE(RAW_Data!I705:I734) -> 98.03125 | H28: =AVERAGE(RAW_Data!J705:J734) -> -57.6625 | I28: =STDEV(RAW_Data!F705:F734) -> 2.4590906 | J28: =STDEV(RAW_Data!G705:G734) -> 0 | K28: =STDEV(RAW_Data!H705:H734) -> 0 | L28: =STDEV(RAW_Data!I705:I734) -> 1.5823577 | M28: =STDEV(RAW_Data!J705:J734) -> 3.1741915
A29: =AVERAGE(RAW_Data!A736:A765) -> -36 | B29: =AVERAGE(RAW_Data!B736:B765) -> -36 | C29: =AVERAGE(RAW_Data!E736:E765) -> 0 | D29: =AVERAGE(RAW_Data!F736:F765) -> 187.96667 | E29: =AVERAGE(RAW_Data!G736:G765) -> -60 | F29: =AVERAGE(RAW_Data!H736:H765) -> -60 | G29: =AVERAGE(RAW_Data!I736:I765) -> 75.496875 | H29: =AVERAGE(RAW_Data!J736:J765) -> -49.266667 | I29: =STDEV(RAW_Data!F736:F765) -> 3.4087447 | J29: =STDEV(RAW_Data!G736:G765) -> 0 | K29: =STDEV(RAW_Data!H736:H765) -> 0 | L29: =STDEV(RAW_Data!I736:I765) -> 1.9865455 | M29: =STDEV(RAW_Data!J736:J765) -> 2.0497004
A30: =AVERAGE(RAW_Data!A767:A796) -> -24 | B30: =AVERAGE(RAW_Data!B767:B796) -> -36 | C30: =AVERAGE(RAW_Data!E767:E796) -> 0 | D30: =AVERAGE(RAW_Data!F767:F796) -> 186.9 | E30: =AVERAGE(RAW_Data!G767:G796) -> -60 | F30: =AVERAGE(RAW_Data!H767:H796) -> -60 | G30: =AVERAGE(RAW_Data!I767:I796) -> 48.725521 | H30: =AVERAGE(RAW_Data!J767:J796) -> -67.993229 | I30: =STDEV(RAW_Data!F767:F796) -> 3.1878 | J30: =STDEV(RAW_Data!G767:G796) -> 0 | K30: =STDEV(RAW_Data!H767:H796) -> 0 | L30: =STDEV(RAW_Data!I767:I796) -> 1.0046002 | M30: =STDEV(RAW_Data!J767:J796) -> 2.1906216
A31: =AVERAGE(RAW_Data!A797:A826) -> -12 | B31: =AVERAGE(RAW_Data!B797:B826) -> -36 | C31: =AVERAGE(RAW_Data!E797:E826) -> 0 | D31: =AVERAGE(RAW_Data!F797:F826) -> 186 | E31: =AVERAGE(RAW_Data!G797:G826) -> -60 | F31: =AVERAGE(RAW_Data!H797:H826) -> -60 | G31: =AVERAGE(RAW_Data!I797:I826) -> 16.202604 | H31: =AVERAGE(RAW_Data!J797:J826) -> -79.130208 | I31: =STDEV(RAW_Data!F797:F826) -> 3.1948234 | J31: =STDEV(RAW_Data!G797:G826) -> 0 | K31: =STDEV(RAW_Data!H797:H826) -> 0 | L31: =STDEV(RAW_Data!I797:I826) -> 1.2517867 | M31: =STDEV(RAW_Data!J797:J826) -> 1.8677858
A32: =AVERAGE(RAW_Data!A827:A856) -> 0 | B32: =AVERAGE(RAW_Data!B827:B856) -> -36 | C32: =AVERAGE(RAW_Data!E827:E856) -> 0 | D32: =AVERAGE(RAW_Data!F827:F856) -> 186.73333 | E32: =AVERAGE(RAW_Data!G827:G856) -> -60 | F32: =AVERAGE(RAW_Data!H827:H856) -> -60 | G32: =AVERAGE(RAW_Data!I827:I856) -> -17.817708 | H32: =AVERAGE(RAW_Data!J827:J856) -> -84.501563 | I32: =STDEV(RAW_Data!F827:F856) -> 3.1724388 | J32: =STDEV(RAW_Data!G827:G856) -> 0 | K32: =STDEV(RAW_Data!H827:H856) -> 0 | L32: =STDEV(RAW_Data!I827:I856) -> 0.94039901 | M32: =STDEV(RAW_Data!J827:J856) -> 2.1281447
A33: =AVERAGE(RAW_Data!A857:A886) -> 12 | B33: =AVERAGE(RAW_Data!B857:B886) -> -36 | C33: =AVERAGE(RAW_Data!E857:E886) -> 0 | D33: =AVERAGE(RAW_Data!F857:F886) -> 185.96667 | E33: =AVERAGE(RAW_Data!G857:G886) -> -60 | F33: =AVERAGE(RAW_Data!H857:H886) -> -60 | G33: =AVERAGE(RAW_Data!I857:I886) -> -43.260937 | H33: =AVERAGE(RAW_Data!J857:J886) -> -84.554167 | I33: =STDEV(RAW_Data!F857:F886) -> 3.285111 | J33: =STDEV(RAW_Data!G857:G886) -> 0 | K33: =STDEV(RAW_Data!H857:H886) -> 0 | L33: =STDEV(RAW_Data!I857:I886) -> 0.96829061 | M33: =STDEV(RAW_Data!J857:J886) -> 2.2204785
A34: =AVERAGE(RAW_Data!A887:A916) -> 24 | B34: =AVERAGE(RAW_Data!B887:B916) -> -36 | C34: =AVERAGE(RAW_Data!E887:E916) -> 0 | D34: =AVERAGE(RAW_Data!F887:F916) -> 185.83333 | E34: =AVERAGE(RAW_Data!G887:G916) -> -60 | F34: =AVERAGE(RAW_Data!H887:H916) -> -60 | G34: =AVERAGE(RAW_Data!I887:I916) -> -72.189063 | H34: =AVERAGE(RAW_Data!J887:J916) -> -82.188021 | I34: =STDEV(RAW_Data!F887:F916) -> 2.6140645 | J34: =STDEV(RAW_Data!G887:G916) -> 0 | K34: =STDEV(RAW_Data!H887:H916) -> 0 | L34: =STDEV(RAW_Data!I887:I916) -> 0.97848066 | M34: =STDEV(RAW_Data!J887:J916) -> 1.8825838
A35: =AVERAGE(RAW_Data!A917:A946) -> 36 | B35: =AVERAGE(RAW_Data!B917:B946) -> -36 | C35: =AVERAGE(RAW_Data!E917:E946) -> 0 | D35: =AVERAGE(RAW_Data!F917:F946) -> 187.13333 | E35: =AVERAGE(RAW_Data!G917:G946) -> -60 | F35: =AVERAGE(RAW_Data!H917:H946) -> -60 | G35: =AVERAGE(RAW_Data!I917:I946) -> -102.83698 | H35: =AVERAGE(RAW_Data!J917:J946) -> -75.655208 | I35: =STDEV(RAW_Data!F917:F946) -> 3.7484096 | J35: =STDEV(RAW_Data!G917:G946) -> 0 | K35: =STDEV(RAW_Data!H917:H946) -> 0 | L35: =STDEV(RAW_Data!I917:I946) -> 1.4993976 | M35: =STDEV(RAW_Data!J917:J946) -> 2.1572958
A36: =AVERAGE(RAW_Data!A947:A976) -> 48 | B36: =AVERAGE(RAW_Data!B947:B976) -> -36 | C36: =AVERAGE(RAW_Data!E947:E976) -> 0 | D36: =AVERAGE(RAW_Data!F947:F976) -> 187.5 | E36: =AVERAGE(RAW_Data!G947:G976) -> -60 | F36: =AVERAGE(RAW_Data!H947:H976) -> -60 | G36: =AVERAGE(RAW_Data!I947:I976) -> -116.6599 | H36: =AVERAGE(RAW_Data!J947:J976) -> -80.870312 | I36: =STDEV(RAW_Data!F947:F976) -> 3.2562936 | J36: =STDEV(RAW_Data!G947:G976) -> 0 | K36: =STDEV(RAW_Data!H947:H976) -> 0 | L36: =STDEV(RAW_Data!I947:I976) -> 1.0477607 | M36: =STDEV(RAW_Data!J947:J976) -> 2.7400607
A37: =AVERAGE(RAW_Data!A978:A1007) -> 60 | B37: =AVERAGE(RAW_Data!B978:B1007) -> -36 | C37: =AVERAGE(RAW_Data!E978:E1007) -> 0 | D37: =AVERAGE(RAW_Data!F978:F1007) -> 187.03333 | E37: =AVERAGE(RAW_Data!G978:G1007) -> -60 | F37: =AVERAGE(RAW_Data!H978:H1007) -> -60 | G37: =AVERAGE(RAW_Data!I978:I1007) -> -140.89062 | H37: =AVERAGE(RAW_Data!J978:J1007) -> -70.369792 | I37: =STDEV(RAW_Data!F978:F1007) -> 3.8549863 | J37: =STDEV(RAW_Data!G978:G1007) -> 0 | K37: =STDEV(RAW_Data!H978:H1007) -> 0 | L37: =STDEV(RAW_Data!I978:I1007) -> 1.4469796 | M37: =STDEV(RAW_Data!J978:J1007) -> 2.3649484
A38: =AVERAGE(RAW_Data!A1008:A1037) -> -60 | B38: =AVERAGE(RAW_Data!B1008:B1037) -> -24 | C38: =AVERAGE(RAW_Data!E1008:E1037) -> 0 | D38: =AVERAGE(RAW_Data!F1008:F1037) -> 182.8 | E38: =AVERAGE(RAW_Data!G1008:G1037) -> -60 | F38: =AVERAGE(RAW_Data!H1008:H1037) -> -60 | G38: =AVERAGE(RAW_Data!I1008:I1037) -> 120.43385 | H38: =AVERAGE(RAW_Data!J1008:J1037) -> -38.868229 | I38: =STDEV(RAW_Data!F1008:F1037) -> 3.9775231 | J38: =STDEV(RAW_Data!G1008:G1037) -> 0 | K38: =STDEV(RAW_Data!H1008:H1037) -> 0 | L38: =STDEV(RAW_Data!I1008:I1037) -> 1.1126574 | M38: =STDEV(RAW_Data!J1008:J1037) -> 3.1893184
A39: =AVERAGE(RAW_Data!A1039:A1068) -> -48 | B39: =AVERAGE(RAW_Data!B1039:B1068) -> -24 | C39: =AVERAGE(RAW_Data!E1039:E1068) -> 0 | D39: =AVERAGE(RAW_Data!F1039:F1068) -> 188.16667 | E39: =AVERAGE(RAW_Data!G1039:G1068) -> -60 | F39: =AVERAGE(RAW_Data!H1039:H1068) -> -60 | G39: =AVERAGE(RAW_Data!I1039:I1068) -> 92.285938 | H39: =AVERAGE(RAW_Data!J1039:J1068) -> -48.125521 | I39: =STDEV(RAW_Data!F1039:F1068) -> 3.5241368 | J39: =STDEV(RAW_Data!G1039:G1068) -> 0 | K39: =STDEV(RAW_Data!H1039:H1068) -> 0 | L39: =STDEV(RAW_Data!I1039:I1068) -> 1.1054497 | M39: =STDEV(RAW_Data!J1039:J1068) -> 3.2877334
A40: =AVERAGE(RAW_Data!A1069:A1098) -> -36 | B40: =AVERAGE(RAW_Data!B1069:B1098) -> -24 | C40: =AVERAGE(RAW_Data!E1069:E1098) -> 0 | D40: =AVERAGE(RAW_Data!F1069:F1098) -> 187.63333 | E40: =AVERAGE(RAW_Data!G1069:G1098) -> -60 | F40: =AVERAGE(RAW_Data!H1069:H1098) -> -60 | G40: =AVERAGE(RAW_Data!I1069:I1098) -> 70.975521 | H40: =AVERAGE(RAW_Data!J1069:J1098) -> -41.103646 | I40: =STDEV(RAW_Data!F1069:F1098) -> 3.5378089 | J40: =STDEV(RAW_Data!G1069:G1098) -> 0 | K40: =STDEV(RAW_Data!H1069:H1098) -> 0 | L40: =STDEV(RAW_Data!I1069:I1098) -> 1.1576448 | M40: =STDEV(RAW_Data!J1069:J1098) -> 1.5115145
A41: =AVERAGE(RAW_Data!A1099:A1128) -> -24 | B41: =AVERAGE(RAW_Data!B1099:B1128) -> -24 | C41: =AVERAGE(RAW_Data!E1099:E1128) -> 0 | D41: =AVERAGE(RAW_Data!F1099:F1128) -> 187.9 | E41: =AVERAGE(RAW_Data!G1099:G1128) -> -60 | F41: =AVERAGE(RAW_Data!H1099:H1128) -> -60 | G41: =AVERAGE(RAW_Data!I1099:I1128) -> 43.882812 | H41: =AVERAGE(RAW_Data!J1099:J1128) -> -37.356771 | I41: =STDEV(RAW_Data!F1099:F1128) -> 2.8204915 | J41: =STDEV(RAW_Data!G1099:G1128) -> 0 | K41: =STDEV(RAW_Data!H1099:H1128) -> 0 | L41: =STDEV(RAW_Data!I1099:I1128) -> 0.81092094 | M41: =STDEV(RAW_Data!J1099:J1128) -> 1.888547
...
